<?xml version="1.0" ?>
<robot name="RKS" xmlns:xacro="http://www.ros.org/wiki/xacro">

<xacro:include filename="$(find RKS_description)/urdf/materials.xacro" />
<xacro:include filename="$(find RKS_description)/urdf/RKS.trans" />
<xacro:include filename="$(find RKS_description)/urdf/RKS.gazebo" />
<link name="base_link">
  <inertial>
    <origin xyz="0.012675324456453599 -0.04817363006145742 -0.026767812772626697" rpy="0 0 0"/>
    <mass value="1.058555982315344"/>
    <inertia ixx="0.001058" iyy="0.003981" izz="0.004727" ixy="1.9e-05" iyz="-4e-06" ixz="-7.6e-05"/>
  </inertial>
  <visual>
    <origin xyz="0 0 0" rpy="0 0 0"/>
    <geometry>
      <mesh filename="package://RKS_description/meshes/base_link.stl" scale="0.001 0.001 0.001"/>
    </geometry>
    <material name="silver"/>
  </visual>
  <collision>
    <origin xyz="0 0 0" rpy="0 0 0"/>
    <geometry>
      <mesh filename="package://RKS_description/meshes/base_link.stl" scale="0.001 0.001 0.001"/>
    </geometry>
  </collision>
</link>

<link name="right__wheel_1">
  <inertial>
    <origin xyz="3.653712306803114e-07 0.002499686209504636 1.2102723730145204e-07" rpy="0 0 0"/>
    <mass value="0.11097676048805928"/>
    <inertia ixx="2.5e-05" iyy="5e-05" izz="2.5e-05" ixy="0.0" iyz="0.0" ixz="-0.0"/>
  </inertial>
  <visual>
    <origin xyz="0.061009 -0.007144 0.044613" rpy="0 0 0"/>
    <geometry>
      <mesh filename="package://RKS_description/meshes/right__wheel_1.stl" scale="0.001 0.001 0.001"/>
    </geometry>
    <material name="silver"/>
  </visual>
  <collision>
    <origin xyz="0.061009 -0.007144 0.044613" rpy="0 0 0"/>
    <geometry>
      <mesh filename="package://RKS_description/meshes/right__wheel_1.stl" scale="0.001 0.001 0.001"/>
    </geometry>
  </collision>
</link>

<link name="left__wheel__1__1">
  <inertial>
    <origin xyz="3.6537123052071685e-07 -0.002500313790495326 1.2102723635776247e-07" rpy="0 0 0"/>
    <mass value="0.11097676048805928"/>
    <inertia ixx="2.5e-05" iyy="5e-05" izz="2.5e-05" ixy="0.0" iyz="0.0" ixz="-0.0"/>
  </inertial>
  <visual>
    <origin xyz="0.061009 0.102856 0.044613" rpy="0 0 0"/>
    <geometry>
      <mesh filename="package://RKS_description/meshes/left__wheel__1__1.stl" scale="0.001 0.001 0.001"/>
    </geometry>
    <material name="silver"/>
  </visual>
  <collision>
    <origin xyz="0.061009 0.102856 0.044613" rpy="0 0 0"/>
    <geometry>
      <mesh filename="package://RKS_description/meshes/left__wheel__1__1.stl" scale="0.001 0.001 0.001"/>
    </geometry>
  </collision>
</link>

<joint name="Rev1" type="continuous">
  <origin xyz="-0.061009 0.007144 -0.044613" rpy="0 0 0"/>
  <parent link="base_link"/>
  <child link="right__wheel_1"/>
  <axis xyz="0.0 1.0 0.0"/>
</joint>

<joint name="Rev2" type="continuous">
  <origin xyz="-0.061009 -0.102856 -0.044613" rpy="0 0 0"/>
  <parent link="base_link"/>
  <child link="left__wheel__1__1"/>
  <axis xyz="-0.0 -1.0 -0.0"/>
</joint>

</robot>
